Workbook

Sheet Inputs-new
A1: Patient UR | B1: Patient Name | C1: Sex (M/F) | D1: DOB | E1: Height (cm) | F1: Weight (Kg) | G1: Patient Effective Mass (kg) | H1: Injected Activity as per Dose Calibrator (MBq) | I1: Injected Activity- Based on deay correction PET measurement (MBq) | J1: Injected Activity Based PET - Equivalent I-131 | K1: Pet Correction Factor | L1: Injection Time | M1: Reference Dose Preparation (Date/Time) | N1: Reference Dose Activity (MBq) | O1: Reference Source Count (Date/Time) | P1: Volume of Diluted Radioisotope Solution (ml) | Q1: Reference Counts (CPM) | R1: Background Counts (CPM) | S1: Reference (MBq/ml) | T1: Reference Counts (Decay Corrected) | U1: Correction Factor | V1: Scan Time 1 | W1: Whole Body Mean SUV 1 (Bq/ml) | X1: Volume of Whole Body 1 (cm^3) | Y1: Δt (hours) | Z1: Estimate Whole Body Activity (MBq) 1 | AA1: Estimate WB Activity - I-131 (MBq) 1 | AB1: Scan Time 2 | AC1: Whole Body Mean SUV 2 (Bq/ml) | AD1: Volume of Whole Body 2 (cm^3) | AE1: Δt (hours) | AF1: Estimate Whole Body Activity (Bq) 2 | AG1: Estimate WB Activity - I-131 (MBq) 1 | AH1: Scan Time 3 | AI1: Whole Body Mean SUV 3 (Bq/ml) | AJ1: Volume of Whole Body 3 (cm^3) | AK1: Δt (hours) | AL1: Estimate Whole Body Activity (Bq) 3 | AM1: Estimate WB Activity - I-131 (MBq) 1 | AN1: Scan Time 4 | AO1: Whole Body Mean SUV 4 (Bq/ml) | AP1: Volume of Whole Body 4 (cm^3) | AQ1: Δt (hours) | AR1: Estimate Whole Body Activity (Bq) 4 | AS1: Estimate WB Activity - I-131 (MBq) 1 | AT1: Scan Time 5 | AU1: Whole Body Mean SUV 5 (Bq/ml) | AV1: Volume of Whole Body 5 (cm^3) | AW1: Δt (hours) | AX1: Estimate Whole Body Activity (Bq) 5 | AY1: Estimate WB Activity - I-131 (MBq) 1 | AZ1: Time Bloods Taken 1 | BA1: Time Bloods Measured 1 | BB1: Counts (Background Corrected) (CPM) | BC1: Δt (hours) | BD1: Counts (Background & Decay Corrected) | BE1: Counts (I-124 to I-131 Corrected) | BF1: Estimate Blood Activity I124 (MBq/ml) | BG1: Estimate Blood Activity I131 (MBq/ml) | BH1: Time Bloods Taken 2 | BI1: Time Bloods Measured 2 | BJ1: Counts (Background Corrected) (CPM) | BK1: Δt (hours) | BL1: Counts (Background & Decay Corrected) | BM1: Counts (I-124 to I-131 Corrected) | BN1: Estimate Blood Activity I124 (MBq/ml) | BO1: Estimate Blood Activity I131 (MBq/ml) | BP1: Time Bloods Taken 3 | BQ1: Time Bloods Measured 3 | BR1: Counts (Background Corrected) (CPM) | BS1: Δt (hours) | BT1: Counts (Background & Decay Corrected) | BU1: Counts (I-124 to I-131 Corrected) | BV1: Estimate Blood Activity I124 (MBq/ml) | BW1: Estimate Blood Activity I131 (MBq/ml) | BX1: Time Bloods Taken 4 | BY1: Time Bloods Measured 4 | BZ1: Counts (Background Corrected) (CPM) | CA1: Δt (hours) | CB1: Counts (Background & Decay Corrected) | CC1: Counts (I-124 to I-131 Corrected) | CD1: Estimate Blood Activity I124 (MBq/ml) | CE1: Estimate Blood Activity I131 (MBq/ml) | CF1: Time Bloods Taken 5 | CG1: Time Bloods Measured 5 | CH1: Counts (Background Corrected) (CPM) | CI1: Δt (hours) | CJ1: Counts (Background & Decay Corrected) | CK1: Counts (I-124 to I-131 Corrected) | CL1: Estimate Blood Activity I124 (MBq/ml) | CM1: Estimate Blood Activity I131 (MBq/ml) | CN1: WB Activity 1 | CO1: WB Activity 2 | CP1: WB Activity 3 | CQ1: WB Activity 4 | CR1: WB Activity 5 | CS1: Time 1 | CT1: Time 2 | CU1: Time 3 | CV1: Time 4 | CW1: Time 5 | CX1: Non-Normalised Whole Body (m) | CY1: Non-Normalised Whole Body (b) | CZ1: Time 1 | DA1: Time 2 | DB1: Time 3 | DC1: Time 4 | DD1: Time 5 | DE1: Time 6 | DF1: Time 7 | DG1: Time 8 | DH1: Time 9 | DI1: Time 10 | DJ1: Time 11 | DK1: Time 12 | DL1: Time 13 | DM1: Time 14 | DN1: Activity 1 | DO1: Activity 2 | DP1: Activity 3 | DQ1: Activity 4 | DR1: Activity 5 | DS1: Activity 6 | DT1: Activity 7 | DU1: Activity 8 | DV1: Activity 9 | DW1: Activity 10 | DX1: Activity 11 | DY1: Activity 12 | DZ1: Activity 13 | EA1: Activity 14 | EB1: LOGEST Normalised (m) WB | EC1: LOGEST Normalised (b) WB | ED1: Decay Constant WB (Bio + Phys) | EE1: Half Life WB (Bio + Phys) (h) | EF1: Residence Time (h) WB | EG1: Activity 1 | EH1: Activity 2 | EI1: Activity 3 | EJ1: Activity 4 | EK1: Activity 5 | EL1: Time 1 | EM1: Time 2 | EN1: Time 3 | EO1: Time 4 | EP1: Time 5 | EQ1: LOGEST Non-Normalised Blood (m) | ER1: LOGEST Non-Normalised Bloods (b) | ES1: Time 1 Blood | ET1: Time 2 Blood | EU1: Time 3 Blood | EV1: Time 4 Blood | EW1: Time 5 Blood | EX1: Time 6 Blood | EY1: Time 7 Blood | EZ1: Time 8 Blood | FA1: Time 9 Blood | FB1: Time 10 Blood | FC1: Time 11 Blood | FD1: Blood 12 Blood | FE1: Time 13 Blood | FF1: Time 14 Blood | FG1: Time 15 Blood | FH1: Time 16 Blood | FI1: Time 17 Blood | FJ1: Time 18 Blood | FK1: Activity 1 Blood | FL1: Activity 2 Blood | FM1: Activity 3 Blood | FN1: Activity 4 Blood | FO1: Activity 5 Blood | FP1: Activity 6 Blood | FQ1: Activity 7 Blood | FR1: Activity 8 Blood | FS1: Activity 9 Blood | FT1: Activity 10 Blood | FU1: Activity 11 Blood | FV1: Activity 12 Blood | FW1: Activity 13 Blood | FX1: Activity 14 Blood | FY1: Activity 15 Blood | FZ1: Activity 16 Blood | GA1: Activity 17 Blood | GB1: Activity 18 Blood | GC1: LOGEST Blood Normalised (m) | GD1: LOGEST Blood Normalised (b) | GE1: Decay Constant Biological Blood (h^-1) | GF1: Biological Half Life Blood (h) | GG1: Effective Half-Life Blood(Bio+Phys) (h) for I-131 | GH1: Residence Time Blood (h) | GI1: LUNGS (GBq) | GK1: S(Blood<- WB) | GL1: Absorbed Dose/ Per Activity (Gy/GBq.h) | GM1: Max Dose (GBq) | GO1: GBq | GP1: mCi | GQ1: GBq | GR1: mCi | GS1: Nodal Activity Time 1 (KBq/ml) | GT1: Measured Volume 1 (cm^3) | GU1: Measured Background 1 (kBq/ml) | GV1: Date Time 1 | GW1: Time post Injection 1 | GX1: Diameter of the Node (mm) | GY1: Volume/ Mass of Node (g) - Assume Spherical | GZ1: Initial activity concentration (MBq/g) - C0 | HA1: Nodal Activity Time 2 (KBq/ml) | HB1: Volume Measured 2 (cm3) | HC1: Measured Background 2 (kBq/ml) | HD1: Date/Time 2 | HE1: Time Post Injection 2 | HF1: Nodal Activity Time 3 (KBq/ml) | HG1: Volume Measured 3 (cm3) | HH1: Measured Background 3 (kBq/ml) | HI1: Date/Time 3 | HJ1: Time Post Injection 3 | HK1: Nodal Activity Time 4 (KBq/ml) | HL1: Volume Measured 4 (cm3) | HM1: Measured Background 4 (kBq/ml) | HN1: Date/Time 4 | HO1: Time Post Injection 4 | HP1: Nodal Activity Time 5 (KBq/ml) | HQ1: Volume Measured 5 (cm3) | HR1: Measured Background 5 (kBq/ml) | HS1: Date/Time 5 | HT1: Time Post Injection 5 | HU1: Time 1 | HV1: Time 2 | HW1: Time 3 | HX1: Time 4 | HY1: Time 5 | HZ1: Activity 1 | IA1: Activity 2 | IB1: Activity 3 | IC1: Activity 4 | ID1: Activity 5 | IE1: Activity (Decay Corrected 1) | IF1: Activity (Decay Corrected 2) | IG1: Activity (Decay Corrected3) | IH1: Activity (Decay Corrected 4) | II1: Activity (Decay Corrected 5) | IJ1: Decay Constant (m) | IK1: Decay Constant (b) | IL1: m = e^-lamba LN(m) | IM1: Biological Half Life | IN1: Effective Half-Life (I-131) | IO1: Initial Activity Concentration (b0) (kBq/ml) | IP1: Initial Activity Concentration per Injected Activity (kBq/ml *Mbq) | IQ1: Integration Factor (Decay Constant for effective half life) | IR1: Cumulated Activity Conc (MBq*h/ml)/MBq | IS1: I-131 Dose Factor (mGy*ml/MBq*h) | IT1: Dose per mGy/MBq | IU1: Dose per Gy/MBq | IV1: Dose Required for 80Gy to Tumour (GBq)
A2: 1 | C2: M | E2: 183 | F2: 125.4 | G2: =IF(C2 = "M", 65.76+(1.452*(E2-152)), 62.34+(1.247*(E2-152))) -> 110.772 | I2: =AA2*EXP(DATA!$B$4*Y2) -> 94.038521 | L2: 43423.625 | M2: 43423.644 | N2: 3.67 | O2: 43425.375 | P2: 200 | Q2: 61327 | S2: =N2/P2 -> 0.01835 | T2: =Q2*EXP((O2-M2)*24*DATA!$B$4) -> 81720.443 | U2: =T2/S2 -> 4453430.1 | V2: 43423.708 | W2: 380.2 | X2: 242335.35 | Y2: =IF(V2="","",(V2-$L2)*24) -> 2 | Z2: =IF(W2 = "", "", W2*X2/1000000) -> 92.1359 | AA2: =IF(Z2 = "", "", Z2*EXP(Y2*DATA!$B$4)*EXP(-DATA!$B$5*'Inputs-new'!Y2)) -> 92.747966 | AB2: 43424.331 | AC2: 192.2 | AD2: 254900.8 | AE2: =IF(AB2="","",(AB2-$L2)*24) -> 16.95 | AF2: =IF(AC2 = "", "", AC2*AD2/1000000) -> 48.991934 | AG2: =IF(AF2 = "", "", AF2*EXP(AE2*DATA!$B$4)*EXP(-DATA!$B$5*'Inputs-new'!AE2)) -> 51.819659 | AH2: 43425 | AI2: 109.8 | AJ2: 240438.39 | AK2: =IF(AH2="","",(AH2-$L2)*24) -> 33 | AL2: =IF(AI2 = "", "", AI2*AJ2/1000000) -> 26.400135 | AM2: =IF(AL2 = "", "", AL2*EXP(AK2*DATA!$B$4)*EXP(-DATA!$B$5*'Inputs-new'!AK2)) -> 29.44775 | AN2: 43426.333 | AO2: 56 | AP2: 228751.2 | AQ2: =IF(AN2="","",(AN2-$L2)*24) -> 65 | AR2: =IF(AO2 = "", "", AO2*AP2/1000000) -> 12.810067 | AS2: =IF(AR2 = "", "", AR2*EXP(AQ2*DATA!$B$4)*EXP(-DATA!$B$5*'Inputs-new'!AQ2)) -> 15.885671 | AT2: 43427.333 | AU2: 26.5 | AV2: 221386.05 | AW2: =IF(AT2="","",(AT2-$L2)*24) -> 89 | AX2: =IF(AU2 = "", "", AU2*AV2/1000000) -> 5.8667303 | AY2: =IF(AX2 = "", "", AX2*EXP(AW2*DATA!$B$4)*EXP(-DATA!$B$5*'Inputs-new'!AW2)) -> 7.8769202 | AZ2: 43423.694 | BA2: 43427.469 | BB2: 3976 | BC2: =IF(AZ2 = "", "", 24*(AZ2-$L2)) -> 1.6666667 | BD2: =IF(BB2 = "", "", BB2*EXP(DATA!$B$4*(BA2-AZ2)*24)) -> 7434.6337 | BE2: =IF(BD2 = "", "", BD2*EXP(BC2*DATA!$B$4)*EXP(-BC2*DATA!$B$5)) -> 7475.7684 | BF2: =BD2*$S$2/$T$2 -> 0.0016694174 | BG2: =BE2*($S$2/$T$2) -> 0.001678654 | BH2: 43424.322 | BI2: 43427.47 | BJ2: 3509 | BK2: =IF(BH2 = "", "", 24*(BH2-$L2)) -> 16.733333 | BL2: =IF(BJ2 = "", "", BJ2*EXP(DATA!$B$4*(BI2-BH2)*24)) -> 5914.0648 | BM2: =IF(BL2 = "", "", BL2*EXP(BK2*DATA!$B$4)*EXP(-BK2*DATA!$B$5)) -> 6250.9286 | BN2: =BL2*$S$2/$T$2 -> 0.0013279797 | BO2: =BM2*($S$2/$T$2) -> 0.0014036211 | BP2: 43425.326 | BQ2: 43427.472 | BR2: 1835 | BS2: =IF(BP2 = "", "", 24*(BP2-$L2)) -> 40.833333 | BT2: =IF(BR2 = "", "", BR2*EXP(DATA!$B$4*(BQ2-BP2)*24)) -> 2618.9185 | BU2: =IF(BT2 = "", "", BT2*EXP(BS2*DATA!$B$4)*EXP(-BS2*DATA!$B$5)) -> 2997.9914 | BV2: =BT2*$S$2/$T$2 -> 0.00058806773 | BW2: =BU2*($S$2/$T$2) -> 0.00067318702 | BX2: 43426.34 | BY2: 43427.473 | BZ2: 1229 | CA2: =IF(BX2 = "", "", 24*(BX2-$L2)) -> 65.166667 | CB2: =IF(BZ2 = "", "", BZ2*EXP(DATA!$B$4*(BY2-BX2)*24)) -> 1482.9307 | CC2: =IF(CB2 = "", "", CB2*EXP(CA2*DATA!$B$4)*EXP(-CA2*DATA!$B$5)) -> 1839.9865 | CD2: =CB2*$S$2/$T$2 -> 0.00033298618 | CE2: =CC2*($S$2/$T$2) -> 0.00041316165 | CF2: 43427.375 | CG2: 43427.474 | CH2: 687 | CI2: =IF(CF2 = "", "", 24*(CF2-$L2)) -> 90 | CJ2: =IF(CH2 = "", "", CH2*EXP(DATA!$B$4*(CG2-CF2)*24)) -> 698.4067 | CK2: =IF(CJ2 = "", "", CJ2*EXP(CI2*DATA!$B$4)*EXP(-CI2*DATA!$B$5)) -> 940.81986 | CL2: =CJ2*$S$2/$T$2 -> 0.00015682444 | CM2: =CK2*($S$2/$T$2) -> 0.00021125735 | CN2: =AA2 -> 92.747966 | CO2: =AG2 -> 51.819659 | CP2: =AM2 -> 29.44775 | CQ2: =AS2 -> 15.885671 | CR2: =AY2 -> 7.8769202 | CS2: =Y2 -> 2 | CT2: =AE2 -> 16.95 | CU2: =AK2 -> 33 | CV2: =AQ2 -> 65 | CW2: =AW2 -> 89 | CX2: {=LOGEST(CN2:CR2, CS2:CW2, TRUE, FALSE)} -> 0.97331581 | CY2: 85.796477 | CZ2: 0 | DA2: 2 | DB2: 4 | DC2: 10 | DD2: 18 | DE2: 24 | DF2: 26 | DG2: 34 | DH2: 42 | DI2: 48 | DJ2: 50 | DK2: 58 | DL2: 66 | DM2: 74 | DN2: =($CY$2*$CX$2^CZ2)/$I2 -> 0.9123546 | DO2: =($CY$2*$CX$2^DA2)/$I2 -> 0.86431335 | DP2: =($CY$2*$CX$2^DB2)/$I2 -> 0.81880178 | DQ2: =($CY$2*$CX$2^DC2)/$I2 -> 0.6961478 | DR2: =($CY$2*$CX$2^DD2)/$I2 -> 0.56070146 | DS2: =($CY$2*$CX$2^DE2)/$I2 -> 0.47671011 | DT2: =($CY$2*$CX$2^DF2)/$I2 -> 0.45160831 | DU2: =($CY$2*$CX$2^DG2)/$I2 -> 0.36374091 | ... EA2: =($CY$2*$CX$2^DM2)/$I2 -> 0.12329439 | EB2: {=LOGEST(DN2:EA2, CZ2:DM2, TRUE, TRUE)} -> 0.97331581 | EC2: 0.9123546 | ED2: =-LN(DW2/DN2)/DI2 -> 0.027046673 | EE2: =LN(2)/ED2 -> 25.627817 | EF2: =(EC2*EE2)/LN(2) -> 33.7326 | EG2: =BG2 -> 0.001678654 | EH2: =BO2 -> 0.0014036211 | EI2: =BW2 -> 0.00067318702 | EJ2: =CE2 -> 0.00041316165 | EK2: =CM2 -> 0.00021125735 | EL2: =BC2 -> 1.6666667 | EM2: =BK2 -> 16.733333 | EN2: =BS2 -> 40.833333 | EO2: =CA2 -> 65.166667 | EP2: =CI2 -> 90 | EQ2: 0.980234 | ER2: 0.001772335 | ES2: 0 | ET2: 2 | EU2: 4 | EV2: 10 | EW2: 18 | EX2: 24 | EY2: 26 | EZ2: 34 | FA2: 42 | FB2: 48 | FC2: 50 | FD2: 58 | FE2: 66 | FF2: 72 | FG2: 78 | FH2: 84 | FI2: 90 | FJ2: 96 | FK2: =($ER2*$EQ$2^ES2)/$I2 -> 1.8846904e-05 | FL2: =($ER2*$EQ$2^ET2)/$I2 -> 1.8109212e-05 | FM2: =($ER2*$EQ$2^EU2)/$I2 -> 1.7400394e-05 | FN2: =($ER2*$EQ$2^EV2)/$I2 -> 1.5436102e-05 | FO2: =($ER2*$EQ$2^EW2)/$I2 -> 1.3157572e-05 | FP2: =($ER2*$EQ$2^EX2)/$I2 -> 1.1672243e-05 | FQ2: =($ER2*$EQ$2^EY2)/$I2 -> 1.1215376e-05 | FR2: =($ER2*$EQ$2^EZ2)/$I2 -> 9.5598689e-06 | ... GB2: =($ER2*$EQ$2^FJ2)/$I2 -> 2.7726637e-06 | GC2: {=LOGEST(FK2:GB2, ES2:FJ2, TRUE, TRUE)} -> 0.980234 | GD2: 1.8846904e-05 | GE2: =-LN(#REF!/#REF!)/#REF! -> #REF! | GF2: =LN(2)/GE2 -> #REF! | GG2: =(GF2*DATA!$B$3)/(DATA!$B$3+#REF!) -> #REF! | GH2: =(GG2*GD2)/LN(2) -> #REF! | GI2: =DATA!B6/DW2 -> 11.883562 | GK2: =IF(G2<F2, 0.0188*(G2^(-2/3)), 0.0188*F2^(-2/3)) -> 0.00081508803 | GL2: =GK2*EF2 + GH2*DATA!$B$8 -> #REF! | GM2: =DATA!B7/GL2 -> #REF! | GO2: =GI2 -> 11.883562 | GP2: =ROUNDDOWN(GO2*27.027,0) -> 321 | GQ2: =GM2 -> #REF! | GR2: =ROUNDDOWN(GQ2 * 27.027,0) -> #REF! | GV2: =V2 -> 43423.708 | GW2: =Y2 -> 2 | GY2: =IF(GX2 = "", "", 0.001 * 4/3 *3.14159265*(GX2/2)^3) | GZ2: =IF(GS2 = "", "", GS2/GY2) | HD2: =AB2 -> 43424.331 | HE2: =AE2 -> 16.95 | HI2: =AH2 -> 43425 | HJ2: =AK2 -> 33 | HN2: =AN2 -> 43426.333 | HO2: =AQ2 -> 65 | HS2: =AT2 -> 43427.333 | HT2: =AW2 -> 89 | IL2: =IF(IK2="","",-LN(IJ2)) | IM2: =LN(2)/IL2 -> #VALUE!
A3: 2 | C3: F | E3: 168 | F3: 73 | G3: =IF(C3 = "M", 65.76+(1.452*(E3-152)), 62.34+(1.247*(E3-152))) -> 82.292 | I3: =AA3*EXP(DATA!$B$4*Y3) -> 37.319186 | K3: 0.61176471 | L3: 44144.651 | M3: 44144.674 | N3: 8.05 | O3: 44152.427 | P3: 200 | Q3: 125373.5 | S3: =N3/P3 -> 0.04025 | T3: =Q3*EXP((O3-M3)*24*DATA!$B$4) -> 453456.44 | U3: =T3/S3 -> 11265998 | V3: 44144.753 | W3: 178.7 | X3: 203672.97 | Y3: =IF(V3="","",(V3-$L3)*24) -> 2.45 | Z3: =IF(W3 = "", "", W3*X3/1000000) -> 36.39636 | AA3: =IF(Z3 = "", "", Z3*EXP(Y3*DATA!$B$4)*EXP(-DATA!$B$5*'Inputs-new'!Y3)) -> 36.692766 | AB3: 44145.337 | AC3: 138.2 | AD3: 191526 | AE3: =IF(AB3="","",(AB3-$L3)*24) -> 16.45 | AF3: =IF(AC3 = "", "", AC3*AD3/1000000) -> 26.468893 | AG3: =IF(AF3 = "", "", AF3*EXP(AE3*DATA!$B$4)*EXP(-DATA!$B$5*'Inputs-new'!AE3)) -> 27.950326 | AH3: 44146.34 | AI3: 78.5 | AJ3: 221618.9 | AK3: =IF(AH3="","",(AH3-$L3)*24) -> 40.533333 | AL3: =IF(AI3 = "", "", AI3*AJ3/1000000) -> 17.397084 | AM3: =IF(AL3 = "", "", AL3*EXP(AK3*DATA!$B$4)*EXP(-DATA!$B$5*'Inputs-new'!AK3)) -> 19.895438 | AN3: 44148.31 | AO3: 27.8 | AP3: 202103.07 | AQ3: =IF(AN3="","",(AN3-$L3)*24) -> 87.8 | AR3: =IF(AO3 = "", "", AO3*AP3/1000000) -> 5.6184653 | AS3: =IF(AR3 = "", "", AR3*EXP(AQ3*DATA!$B$4)*EXP(-DATA!$B$5*'Inputs-new'!AQ3)) -> 7.5136804 | AW3: =IF(AT3="","",(AT3-$L3)*24) | AX3: =IF(AU3 = "", "", AU3*AV3/1000000) | AY3: =IF(AX3 = "", "", AX3*EXP(AW3*DATA!$B$4)*EXP(-DATA!$B$5*'Inputs-new'!AW3)) | AZ3: 44144.74 | BA3: 44152.427 | BB3: 7168.75 | BC3: =IF(AZ3 = "", "", 24*(AZ3-$L3)) -> 2.1166667 | BD3: =IF(BB3 = "", "", BB3*EXP(DATA!$B$4*(BA3-AZ3)*24)) -> 25649.102 | BE3: =IF(BD3 = "", "", BD3*EXP(BC3*DATA!$B$4)*EXP(-BC3*DATA!$B$5)) -> 25829.465 | BF3: =BD3*$S$3/$T$3 -> 0.0022766825 | BG3: =BE3*($S$3/$T$3) -> 0.0022926921 | BH3: 44145.323 | BI3: 44152.427 | BJ3: 5839.5 | BK3: =IF(BH3 = "", "", 24*(BH3-$L3)) -> 16.116667 | BL3: =IF(BJ3 = "", "", BJ3*EXP(DATA!$B$4*(BI3-BH3)*24)) -> 18966.824 | BM3: =IF(BL3 = "", "", BL3*EXP(BK3*DATA!$B$4)*EXP(-BK3*DATA!$B$5)) -> 20006.286 | BN3: =BL3*$S$3/$T$3 -> 0.0016835458 | BO3: =BM3*($S$3/$T$3) -> 0.0017758111 | BP3: 44146.333 | BQ3: 44152.427 | BR3: 4446 | BS3: =IF(BP3 = "", "", 24*(BP3-$L3)) -> 40.366667 | BT3: =IF(BR3 = "", "", BR3*EXP(DATA!$B$4*(BQ3-BP3)*24)) -> 12212.976 | BU3: =IF(BT3 = "", "", BT3*EXP(BS3*DATA!$B$4)*EXP(-BS3*DATA!$B$5)) -> 13959.149 | BV3: =BT3*$S$3/$T$3 -> 0.0010840562 | BW3: =BU3*($S$3/$T$3) -> 0.0012390512 | BX3: 44148.302 | BY3: 44152.427 | BZ3: 1752 | CA3: =IF(BX3 = "", "", 24*(BX3-$L3)) -> 87.616667 | CB3: =IF(BZ3 = "", "", BZ3*EXP(DATA!$B$4*(BY3-BX3)*24)) -> 3472.1876 | CC3: =IF(CB3 = "", "", CB3*EXP(CA3*DATA!$B$4)*EXP(-CA3*DATA!$B$5)) -> 4640.605 | CD3: =CB3*$S$3/$T$3 -> 0.00030820061 | CE3: =CC3*($S$3/$T$3) -> 0.00041191245 | CI3: =IF(CF3 = "", "", 24*(CF3-$L3)) | CJ3: =IF(CH3 = "", "", CH3*EXP(DATA!$B$4*(CG3-CF3)*24)) | CK3: =IF(CJ3 = "", "", CJ3*EXP(CI3*DATA!$B$4)*EXP(-CI3*DATA!$B$5)) | CN3: =AA3 -> 36.692766 | CO3: =AG3 -> 27.950326 | CP3: =AM3 -> 19.895438 | CQ3: =AS3 -> 7.5136804 | CR3: =AY3 | CS3: =Y3 -> 2.45 | CT3: =AE3 -> 16.45 | CU3: =AK3 -> 40.533333 | CV3: =AQ3 -> 87.8 | CW3: =AW3 | CX3: {=LOGEST(CN3:CQ3,CS3:CV3,TRUE, FALSE)} -> 0.98173103 | CY3: 39.006366 | CZ3: 0 | DA3: 2 | DB3: 4 | DC3: 10 | DD3: 18 | DE3: 24 | DF3: 26 | DG3: 34 | DH3: 42 | DI3: 48 | DJ3: 50 | DK3: 58 | DL3: 66 | DM3: 74 | DN3: =($CY$3*$CX$3^CZ3)/$I$3 -> 1.0452095 | DO3: =($CY$3*$CX$3^DA3)/$I$3 -> 1.0073685 | DP3: =($CY$3*$CX$3^DB3)/$I$3 -> 0.97089754 | DQ3: =($CY$3*$CX$3^DC3)/$I$3 -> 0.86921758 | DR3: =($CY$3*$CX$3^DD3)/$I$3 -> 0.75001274 | DS3: =($CY$3*$CX$3^DE3)/$I$3 -> 0.67146556 | DT3: =($CY$3*$CX$3^DF3)/$I$3 -> 0.64715569 | DU3: =($CY$3*$CX$3^DG3)/$I$3 -> 0.5584045 | ... EA3: =($CY$3*$CX$3^DM3)/$I$3 -> 0.26708506 | EB3: {=LOGEST(DN3:EA3, CZ3:DM3, TRUE, TRUE)} -> 0.98173103 | EC3: 1.0452095 | ED3: =-LN(DW3/DN3)/DI3 -> 0.018437911 | EE3: =LN(2)/ED3 -> 37.593585 | EF3: =(EC3*EE3)/LN(2) -> 56.688063 | EG3: =BG3 -> 0.0022926921 | EH3: =BO3 -> 0.0017758111 | EI3: =BW3 -> 0.0012390512 | EJ3: =CE3 -> 0.00041191245 | EL3: =BC3 -> 2.1166667 | EM3: =BK3 -> 16.116667 | EN3: =BS3 -> 40.366667 | EO3: =CA3 -> 87.616667 | EQ3: {=LOGEST(EG3:EJ3, EL3:EO3, TRUE, TRUE)} -> 0.98013568 | ER3: 0.0024999706 | ES3: 0 | ET3: 2 | EU3: 4 | EV3: 10 | EW3: 18 | EX3: 24 | EY3: 26 | EZ3: 34 | FA3: 42 | FB3: 48 | FC3: 50 | FD3: 58 | FE3: 66 | FF3: 72 | FG3: 78 | FH3: 84 | FI3: 90 | FJ3: 96 | FK3: =($ER3*$EQ$3^ES3)/$I3 -> 6.6988883e-05 | FL3: =($ER3*$EQ$3^ET3)/$I3 -> 6.4353939e-05 | FM3: =($ER3*$EQ$3^EU3)/$I3 -> 6.1822638e-05 | FN3: =($ER3*$EQ$3^EV3)/$I3 -> 5.4810621e-05 | FO3: =($ER3*$EQ$3^EW3)/$I3 -> 4.6682523e-05 | FP3: =($ER3*$EQ$3^EX3)/$I3 -> 4.1387721e-05 | FQ3: =($ER3*$EQ$3^EY3)/$I3 -> 3.9759774e-05 | FR3: =($ER3*$EQ$3^EZ3)/$I3 -> 3.386363e-05 | ... GB3: =($ER3*$EQ$3^FJ3)/$I3 -> 9.76063e-06 | GC3: {=LOGEST(FK3:GB3, ES3:FJ3, TRUE, TRUE)} -> 0.98013568 | GD3: 6.6988883e-05 | GE3: =-LN(#REF!/#REF!)/#REF! -> #REF! | GF3: =LN(2)/GE3 -> #REF! | GG3: =(GF3*DATA!$B$3)/(DATA!$B$3+#REF!) -> #REF! | GH3: =(GG3*GD3)/LN(2) -> #REF! | GI3: =DATA!B6/DW3 -> 6.8619502 | GK3: =IF(G3<F3, 0.0188*(G3^(-2/3)), 0.0188*F3^(-2/3)) -> 0.001076323 | GL3: =GK3*EF3 + GH3*DATA!$B$8 -> #REF! | GM3: =DATA!B7/GL3 -> #REF! | GO3: =GI3 -> 6.8619502 | GP3: =ROUNDDOWN(GO3*27.027,0) -> 185 | GQ3: =GM3 -> #REF! | GR3: =ROUNDDOWN(GQ3 * 27.027,0) -> #REF! | GV3: =V3 -> 44144.753 | GW3: =Y3 -> 2.45 | GY3: =IF(GX3 = "", "", 0.001 * 4/3 *3.14159265*(GX3/2)^3) | GZ3: =IF(GS3 = "", "", GS3/GY3) | HD3: =AB3 -> 44145.337 | HE3: =AE3 -> 16.45 | HI3: =AH3 -> 44146.34 | HJ3: =AK3 -> 40.533333 | HN3: =AN3 -> 44148.31 | HO3: =AQ3 -> 87.8 | HS3: =AT3 -> 0 | HT3: =AW3 | IL3: =IF(IK3="","",-LN(IJ3)) | IM3: =LN(2)/IL3 -> #VALUE!
A4: 3 | C4: M | E4: 183 | F4: 124 | G4: =IF(C4 = "M", 65.76+(1.452*(E4-152)), 62.34+(1.247*(E4-152))) -> 110.772 | I4: =AA4*EXP(DATA!$B$4*Y4) -> 81.953906 | K4: 0.9845 | L4: 44214.624 | M4: 44214.64 | N4: 12.497 | O4: 44221.674 | P4: 200 | Q4: 83219.25 | S4: =N4/P4 -> 0.062485 | T4: =Q4*EXP((O4-M4)*24*DATA!$B$4) -> 267141.63 | U4: =T4/S4 -> 4275292.2 | V4: 44214.703 | W4: 280.5 | X4: 286601 | Y4: =IF(V4="","",(V4-$L4)*24) -> 1.8833333 | Z4: =IF(W4 = "", "", W4*X4/1000000) -> 80.391581 | AA4: =IF(Z4 = "", "", Z4*EXP(Y4*DATA!$B$4)*EXP(-DATA!$B$5*'Inputs-new'!Y4)) -> 80.894378 | AB4: 44215.302 | AC4: 171.6 | AD4: 285453 | AE4: =IF(AB4="","",(AB4-$L4)*24) -> 16.266667 | AF4: =IF(AC4 = "", "", AC4*AD4/1000000) -> 48.983735 | AG4: =IF(AF4 = "", "", AF4*EXP(AE4*DATA!$B$4)*EXP(-DATA!$B$5*'Inputs-new'!AE4)) -> 51.693912 | AH4: 44216.301 | AI4: 78.8 | AJ4: 296370.3 | AK4: =IF(AH4="","",(AH4-$L4)*24) -> 40.233333 | AL4: =IF(AI4 = "", "", AI4*AJ4/1000000) -> 23.35398 | AM4: =IF(AL4 = "", "", AL4*EXP(AK4*DATA!$B$4)*EXP(-DATA!$B$5*'Inputs-new'!AK4)) -> 26.681278 | AN4: 44217.287 | AO4: 37.2 | AP4: 295208.51 | AQ4: =IF(AN4="","",(AN4-$L4)*24) -> 63.916667 | AR4: =IF(AO4 = "", "", AO4*AP4/1000000) -> 10.981757 | AS4: =IF(AR4 = "", "", AR4*EXP(AQ4*DATA!$B$4)*EXP(-DATA!$B$5*'Inputs-new'!AQ4)) -> 13.569643 | AT4: 44218.285 | AU4: 12.3 | AV4: 323740.95 | AW4: =IF(AT4="","",(AT4-$L4)*24) -> 87.85 | AX4: =IF(AU4 = "", "", AU4*AV4/1000000) -> 3.9820137 | AY4: =IF(AX4 = "", "", AX4*EXP(AW4*DATA!$B$4)*EXP(-DATA!$B$5*'Inputs-new'!AW4)) -> 5.3261041 | AZ4: 44214.698 | BA4: 44221.674 | BB4: 2382.5 | BC4: =IF(AZ4 = "", "", 24*(AZ4-$L4)) -> 1.7666667 | BD4: =IF(BB4 = "", "", BB4*EXP(DATA!$B$4*(BA4-AZ4)*24)) -> 7575.298 | BE4: =IF(BD4 = "", "", BD4*EXP(BC4*DATA!$B$4)*EXP(-BC4*DATA!$B$5)) -> 7619.733 | BF4: =BD4*$S$4/$T$4 -> 0.0017718784 | BG4: =BE4*$S$4/$T$4 -> 0.0017822719 | BH4: 44215.302 | BI4: 44221.674 | BJ4: 1609.75 | BK4: =IF(BH4 = "", "", 24*(BH4-$L4)) -> 16.266667 | BL4: =IF(BJ4 = "", "", BJ4*EXP(DATA!$B$4*(BI4-BH4)*24)) -> 4630.3639 | BM4: =IF(BL4 = "", "", BL4*EXP(BK4*DATA!$B$4)*EXP(-BK4*DATA!$B$5)) -> 4886.5532 | BN4: =BL4*$S$4/$T$4 -> 0.001083052 | BO4: =BM4*($S$4/$T$4) -> 0.0011429753 | BP4: 44216.347 | BQ4: 44221.674 | BR4: 854.25 | BS4: =IF(BP4 = "", "", 24*(BP4-$L4)) -> 41.35 | BT4: =IF(BR4 = "", "", BR4*EXP(DATA!$B$4*(BQ4-BP4)*24)) -> 2066.2087 | BU4: =IF(BT4 = "", "", BT4*EXP(BS4*DATA!$B$4)*EXP(-BS4*DATA!$B$5)) -> 2369.3292 | BV4: =BT4*$S$4/$T$4 -> 0.00048329064 | BW4: =BU4*$S$4/$T$4 -> 0.00055419118 | BX4: 44217.34 | BY4: 44221.674 | BZ4: 453.25 | CA4: =IF(BX4 = "", "", 24*(BX4-$L4)) -> 65.183333 | CB4: =IF(BZ4 = "", "", BZ4*EXP(DATA!$B$4*(BY4-BX4)*24)) -> 929.84461 | CC4: =IF(CB4 = "", "", CB4*EXP(CA4*DATA!$B$4)*EXP(-CA4*DATA!$B$5)) -> 1153.7936 | CD4: =CB4*$S$4/$T$4 -> 0.00021749265 | CE4: =CC4*($S$4/$T$4) -> 0.0002698748 | CF4: 44218.347 | CG4: 44221.674 | CH4: 255.25 | CI4: =IF(CF4 = "", "", 24*(CF4-$L4)) -> 89.35 | CJ4: =IF(CH4 = "", "", CH4*EXP(DATA!$B$4*(CG4-CF4)*24)) -> 443.1201 | CK4: =IF(CJ4 = "", "", CJ4*EXP(CI4*DATA!$B$4)*EXP(-CI4*DATA!$B$5)) -> 595.64156 | CL4: =CJ4*$S$4/$T$4 -> 0.00010364674 | CM4: =CK4*($S$4/$T$4) -> 0.00013932184 | CN4: =AA4 -> 80.894378 | CO4: =AG4 -> 51.693912 | CP4: =AM4 -> 26.681278 | CQ4: =AS4 -> 13.569643 | CR4: =AY4 -> 5.3261041 | CS4: =Y4 -> 1.8833333 | CT4: =AE4 -> 16.266667 | CU4: =AK4 -> 40.233333 | CV4: =AQ4 -> 63.916667 | CW4: =AW4 -> 87.85 | CX4: {=LOGEST(CN4:CR4, CS4:CW4, TRUE, TRUE)} -> 0.96955043 | CY4: 88.258076 | CZ4: 0 | DA4: 2 | DB4: 4 | DC4: 10 | DD4: 18 | DE4: 24 | DF4: 26 | DG4: 34 | DH4: 42 | DI4: 48 | DJ4: 50 | DK4: 58 | DL4: 66 | DM4: 74 | DN4: =($CY$4*$CX$4^CZ4)/$I$4 -> 1.0769234 | DO4: =($CY$4*$CX$4^DA4)/$I$4 -> 1.0123382 | DP4: =($CY$4*$CX$4^DB4)/$I$4 -> 0.95162624 | DQ4: =($CY$4*$CX$4^DC4)/$I$4 -> 0.79047625 | DR4: =($CY$4*$CX$4^DD4)/$I$4 -> 0.61723714 | DS4: =($CY$4*$CX$4^DE4)/$I$4 -> 0.51271316 | DT4: =($CY$4*$CX$4^DF4)/$I$4 -> 0.48196475 | DU4: =($CY$4*$CX$4^DG4)/$I$4 -> 0.37633837 | ... EA4: =($CY$4*$CX$4^DM4)/$I$4 -> 0.10924325 | EB4: {=LOGEST(DN4:EA4, CZ4:DM4, TRUE, TRUE)} -> 0.96955043 | EC4: 1.0769234 | ED4: =-LN(DW4/DN4)/DI4 -> 0.03092279 | EE4: =LN(2)/ED4 -> 22.415415 | EF4: =(EC4*EE4)/LN(2) -> 34.826203 | EG4: =BG4 -> 0.0017822719 | EH4: =BO4 -> 0.0011429753 | EI4: =BW4 -> 0.00055419118 | EJ4: =CE4 -> 0.0002698748 | EK4: =CM4 -> 0.00013932184 | EL4: =BC4 -> 1.7666667 | EM4: =BK4 -> 16.266667 | EN4: =BS4 -> 41.35 | EO4: =CA4 -> 65.183333 | EP4: =CI4 -> 89.35 | EQ4: {=LOGEST(EG4:EK4, EL4:EP4, TRUE, TRUE)} -> 0.97125396 | ER4: 0.0018514645 | ES4: 0 | ET4: 2 | EU4: 4 | EV4: 10 | EW4: 18 | EX4: 24 | EY4: 26 | EZ4: 34 | FA4: 42 | FB4: 48 | FC4: 50 | FD4: 58 | FE4: 66 | FF4: 72 | FG4: 78 | FH4: 84 | FI4: 90 | FJ4: 96 | FK4: =($ER4*$EQ$4^ES4)/$I4 -> 2.2591535e-05 | FL4: =($ER4*$EQ$4^ET4)/$I4 -> 2.1311369e-05 | FM4: =($ER4*$EQ$4^EU4)/$I4 -> 2.0103744e-05 | FN4: =($ER4*$EQ$4^EV4)/$I4 -> 1.6876164e-05 | FO4: =($ER4*$EQ$4^EW4)/$I4 -> 1.336399e-05 | FP4: =($ER4*$EQ$4^EX4)/$I4 -> 1.1218453e-05 | FQ4: =($ER4*$EQ$4^EY4)/$I4 -> 1.0582751e-05 | FR4: =($ER4*$EQ$4^EZ4)/$I4 -> 8.380327e-06 | ... GB4: =($ER4*$EQ$4^FJ4)/$I4 -> 1.3737085e-06 | GC4: {=LOGEST(FK4:GB4, ES4:FJ4, TRUE, TRUE)} -> 0.97125396 | GD4: 2.2591535e-05 | GE4: =-LN(#REF!/#REF!)/#REF! -> #REF! | GF4: =LN(2)/GE4 -> #REF! | GG4: =(GF4*DATA!$B$3)/(DATA!$B$3+#REF!) -> #REF! | GH4: =(GG4*GD4)/LN(2) -> #REF! | GI4: =DATA!B6/DW4 -> 12.12628 | GK4: =IF(G4<F4, 0.0188*(G4^(-2/3)), 0.0188*F4^(-2/3)) -> 0.00081508803 | GL4: =GK4*EF4 + GH4*DATA!$B$8 -> #REF! | GM4: =DATA!$B$7/GL4 -> #REF! | GO4: =GI4 -> 12.12628 | GP4: =ROUNDDOWN(GO4*27.027,0) -> 327 | GQ4: =GM4 -> #REF! | GR4: =ROUNDDOWN(GQ4 * 27.027,0) -> #REF! | GV4: =V4 -> 44214.703 | GW4: =Y4 -> 1.8833333 | GY4: =IF(GX4 = "", "", 0.001 * 4/3 *3.14159265*(GX4/2)^3) | GZ4: =IF(GS4 = "", "", GS4/GY4) | HD4: =AB4 -> 44215.302 | HE4: =AE4 -> 16.266667 | HI4: =AH4 -> 44216.301 | HJ4: =AK4 -> 40.233333 | HN4: =AN4 -> 44217.287 | HO4: =AQ4 -> 63.916667 | HS4: =AT4 -> 44218.285 | HT4: =AW4 -> 87.85 | IL4: =IF(IK4="","",-LN(IJ4)) | IM4: =LN(2)/IL4 -> #VALUE!
A5: 4 | C5: M | E5: 183 | F5: 124 | G5: =IF(C5 = "M", 65.76+(1.452*(E5-152)), 62.34+(1.247*(E5-152))) -> 110.772 | I5: =AA5*EXP(DATA!$B$4*Y5) -> 70.960275 | L5: 44242.618 | V5: 44242.69 | W5: 194.3 | X5: 358797.3 | Y5: =IF(V5="","",(V5-$L5)*24) -> 1.7333333 | Z5: =IF(W5 = "", "", W5*X5/1000000) -> 69.714315 | AA5: =IF(Z5 = "", "", Z5*EXP(Y5*DATA!$B$4)*EXP(-DATA!$B$5*'Inputs-new'!Y5)) -> 70.115507 | AB5: 44243.296 | AC5: 164.9 | AD5: 323813.31 | AE5: =IF(AB5="","",(AB5-$L5)*24) -> 16.266667 | AF5: =IF(AC5 = "", "", AC5*AD5/1000000) -> 53.396815 | AG5: =IF(AF5 = "", "", AF5*EXP(AE5*DATA!$B$4)*EXP(-DATA!$B$5*'Inputs-new'!AE5)) -> 56.351159 | AH5: 44244.305 | AI5: 84.1 | AJ5: 331043 | AK5: =IF(AH5="","",(AH5-$L5)*24) -> 40.483333 | AL5: =IF(AI5 = "", "", AI5*AJ5/1000000) -> 27.840716 | AM5: =IF(AL5 = "", "", AL5*EXP(AK5*DATA!$B$4)*EXP(-DATA!$B$5*'Inputs-new'!AK5)) -> 31.833587 | AN5: 44245.315 | AO5: 41.3 | AP5: 331944.12 | AQ5: =IF(AN5="","",(AN5-$L5)*24) -> 64.733333 | AR5: =IF(AO5 = "", "", AO5*AP5/1000000) -> 13.709292 | AS5: =IF(AR5 = "", "", AR5*EXP(AQ5*DATA!$B$4)*EXP(-DATA!$B$5*'Inputs-new'!AQ5)) -> 16.985792 | AW5: =IF(AT5="","",(AT5-$L5)*24) | AX5: =IF(AU5 = "", "", AU5*AV5/1000000) | AY5: =IF(AX5 = "", "", AX5*EXP(AW5*DATA!$B$4)*EXP(-DATA!$B$5*'Inputs-new'!AW5)) | BC5: =IF(AZ5 = "", "", 24*(AZ5-$L5)) | BD5: =IF(BB5 = "", "", BB5*EXP(DATA!$B$4*(BA5-AZ5)*24)) | BE5: =IF(BD5 = "", "", BD5*EXP(BC5*DATA!$B$4)*EXP(-BC5*DATA!$B$5)) | BK5: =IF(BH5 = "", "", 24*(BH5-$L5)) | BL5: =IF(BJ5 = "", "", BJ5*EXP(DATA!$B$4*(BI5-BH5)*24)) | BM5: =IF(BL5 = "", "", BL5*EXP(BK5*DATA!$B$4)*EXP(-BK5*DATA!$B$5)) | BN5: =BL5*$S$4/$T$4 -> #VALUE! | BT5: =IF(BR5 = "", "", BR5*EXP(DATA!$B$4*(BQ5-BP5)*24)) | BU5: =IF(BT5 = "", "", BT5*EXP(BS5*DATA!$B$4)*EXP(-BS5*DATA!$B$5)) | BW5: =BU5*$S$4/$T$4 -> #VALUE! | CA5: =IF(BX5 = "", "", 24*(BX5-$L5)) | CB5: =IF(BZ5 = "", "", BZ5*EXP(DATA!$B$4*(BY5-BX5)*24)) | CC5: =IF(CB5 = "", "", CB5*EXP(CA5*DATA!$B$4)*EXP(-CA5*DATA!$B$5)) | CI5: =IF(CF5 = "", "", 24*(CF5-$L5)) | CJ5: =IF(CH5 = "", "", CH5*EXP(DATA!$B$4*(CG5-CF5)*24)) | CK5: =IF(CJ5 = "", "", CJ5*EXP(CI5*DATA!$B$4)*EXP(-CI5*DATA!$B$5)) | CL5: =CJ5*$S$4/$T$4 -> #VALUE! | CM5: =CK5*($S$4/$T$4) -> #VALUE! | CN5: =AA5 -> 70.115507 | CO5: =AG5 -> 56.351159 | CP5: =AM5 -> 31.833587 | CQ5: =AS5 -> 16.985792 | CR5: =AY5 | CS5: =Y5 -> 1.7333333 | CT5: =AE5 -> 16.266667 | CU5: =AK5 -> 40.483333 | CV5: =AQ5 -> 64.733333 | CW5: =AW5 | CX5: {=LOGEST(CN5:CQ5,CS5:CV5,TRUE,TRUE)} -> 0.97741581 | CY5: 77.271467 | CZ5: 0 | DA5: 2 | DB5: 4 | DC5: 10 | DD5: 18 | DE5: 24 | DF5: 26 | DG5: 34 | DH5: 42 | DI5: 48 | DJ5: 50 | DK5: 58 | DL5: 66 | DM5: 74 | DN5: =($CY$5*$CX$5^CZ5)/$I$5 -> 1.0889398 | DO5: =($CY$5*$CX$5^DA5)/$I$5 -> 1.0403096 | DP5: =($CY$5*$CX$5^DB5)/$I$5 -> 0.99385106 | DQ5: =($CY$5*$CX$5^DC5)/$I$5 -> 0.86655764 | DR5: =($CY$5*$CX$5^DD5)/$I$5 -> 0.72182568 | DS5: =($CY$5*$CX$5^DE5)/$I$5 -> 0.62937355 | DT5: =($CY$5*$CX$5^DF5)/$I$5 -> 0.60126677 | DU5: =($CY$5*$CX$5^DG5)/$I$5 -> 0.50084354 | ... EA5: =($CY$5*$CX$5^DM5)/$I$5 -> 0.20085213 | EB5: {=LOGEST(DN5:EA5, CZ5:DM5, TRUE, TRUE)} -> 0.97741581 | EC5: 1.0889398 | ED5: =-LN(DW5/DN5)/DI5 -> 0.02284312 | EE5: =LN(2)/ED5 -> 30.343805 | EF5: =(EC5*EE5)/LN(2) -> 47.670362 | EL5: =BC5 | EM5: =BK5 | EN5: =BS5 -> 0 | EO5: =CA5 | EP5: =CI5 | GI5: =DATA!$B$6/DW5 -> 8.1372678 | GK5: =IF(G5<F5, 0.0188*(G5^(-2/3)), 0.0188*F5^(-2/3)) -> 0.00081508803 | GL5: =GK5*EF5 + GH5*DATA!$B$8 -> 0.038855541 | GM5: =DATA!$B$7/GL5 -> 51.47271 | GO5: =GI5 -> 8.1372678 | GP5: =ROUNDDOWN(GO5*27.027,0) -> 219 | GQ5: =GM5 -> 51.47271 | GR5: =ROUNDDOWN(GQ5 * 27.027,0) -> 1391 | GW5: =Y5 -> 1.7333333 | GY5: =IF(GX5 = "", "", 0.001 * 4/3 *3.14159265*(GX5/2)^3) | GZ5: =IF(GS5 = "", "", GS5/GY5) | HD5: =AB5 -> 44243.296 | HE5: =AE5 -> 16.266667 | HI5: =AH5 -> 44244.305 | HJ5: =AK5 -> 40.483333 | HN5: =AN5 -> 44245.315 | HO5: =AQ5 -> 64.733333 | HS5: =AT5 -> 0 | HT5: =AW5 | IL5: =IF(IK5="","",-LN(IJ5)) | IM5: =LN(2)/IL5 -> #VALUE!
A6: 5 | C6: M | E6: 175 | F6: 84 | G6: =IF(C6 = "M", 65.76+(1.452*(E6-152)), 62.34+(1.247*(E6-152))) -> 99.156 | H6: 72.13 | I6: =AA6*EXP(DATA!$B$4*Y6) -> 63.938076 | L6: 44326.633 | M6: 44326.619 | N6: 11.67 | O6: 44334.5 | P6: 200 | Q6: 50153.5 | S6: =N6/P6 -> 0.05835 | T6: =Q6*EXP((O6-M6)*24*DATA!$B$4) -> 185281.99 | U6: =T6/S6 -> 3175355.5 | V6: 44326.715 | W6: 250 | X6: 250663.21 | Y6: =IF(V6="","",(V6-$L6)*24) -> 1.9666667 | Z6: =IF(W6 = "", "", W6*X6/1000000) -> 62.665802 | AA6: =IF(Z6 = "", "", Z6*EXP(Y6*DATA!$B$4)*EXP(-DATA!$B$5*'Inputs-new'!Y6)) -> 63.075136 | AB6: 44327.321 | AC6: 112.4 | AD6: 265975.74 | AE6: =IF(AB6="","",(AB6-$L6)*24) -> 16.5 | AF6: =IF(AC6 = "", "", AC6*AD6/1000000) -> 29.895673 | AG6: =IF(AF6 = "", "", AF6*EXP(AE6*DATA!$B$4)*EXP(-DATA!$B$5*'Inputs-new'!AE6)) -> 31.574125 | AH6: 44328.328 | AI6: 38.2 | AJ6: 305202.43 | AK6: =IF(AH6="","",(AH6-$L6)*24) -> 40.666667 | AL6: =IF(AI6 = "", "", AI6*AJ6/1000000) -> 11.658733 | AM6: =IF(AL6 = "", "", AL6*EXP(AK6*DATA!$B$4)*EXP(-DATA!$B$5*'Inputs-new'!AK6)) -> 13.338903 | AN6: 44329.328 | AO6: 12.2 | AP6: 266048 | AQ6: =IF(AN6="","",(AN6-$L6)*24) -> 64.683333 | AR6: =IF(AO6 = "", "", AO6*AP6/1000000) -> 3.2457856 | AS6: =IF(AR6 = "", "", AR6*EXP(AQ6*DATA!$B$4)*EXP(-DATA!$B$5*'Inputs-new'!AQ6)) -> 4.0208577 | AT6: 44330.322 | AU6: 3.23 | AV6: 276910 | AW6: =IF(AT6="","",(AT6-$L6)*24) -> 88.516667 | AX6: =IF(AU6 = "", "", AU6*AV6/1000000) -> 0.8944193 | AY6: =IF(AX6 = "", "", AX6*EXP(AW6*DATA!$B$4)*EXP(-DATA!$B$5*'Inputs-new'!AW6)) -> 1.1989652 | AZ6: 44326.668 | BA6: 44334.5 | BB6: 2668 | BC6: =IF(AZ6 = "", "", 24*(AZ6-$L6)) -> 0.83333333 | BD6: =IF(BB6 = "", "", BB6*EXP(DATA!$B$4*(BA6-AZ6)*24)) -> 9777.2557 | BE6: =IF(BD6 = "", "", BD6*EXP(BC6*DATA!$B$4)*EXP(-BC6*DATA!$B$5)) -> 9804.2664 | BF6: =BD6*$S$6/$T$6 -> 0.0030791059 | BG6: =BE6*$S$6/$T$6 -> 0.0030876123 | BH6: 44327.316 | BI6: 44334.5 | BJ6: 1537.5 | BK6: =IF(BH6 = "", "", 24*(BH6-$L6)) -> 16.383333 | BL6: =IF(BJ6 = "", "", BJ6*EXP(DATA!$B$4*(BI6-BH6)*24)) -> 5060.4067 | BM6: =IF(BL6 = "", "", BL6*EXP(BK6*DATA!$B$4)*EXP(-BK6*DATA!$B$5)) -> 5342.4525 | BN6: =BL6*$S$6/$T$6 -> 0.0015936505 | BO6: =BM6*($S$6/$T$6) -> 0.0016824738 | BP6: 44328.372 | BQ6: 44334.5 | BR6: 575.75 | BS6: =IF(BP6 = "", "", 24*(BP6-$L6)) -> 41.716667 | BT6: =IF(BR6 = "", "", BR6*EXP(DATA!$B$4*(BQ6-BP6)*24)) -> 1590.6937 | BU6: =IF(BT6 = "", "", BT6*EXP(BS6*DATA!$B$4)*EXP(-BS6*DATA!$B$5)) -> 1826.27 | BV6: =BT6*$S$6/$T$6 -> 0.00050094982 | BW6: =BU6*$S$6/$T$6 -> 0.00057513875 | BX6: 44329.317 | BY6: 44334.5 | BZ6: 231.5 | CA6: =IF(BX6 = "", "", 24*(BX6-$L6)) -> 64.416667 | CB6: =IF(BZ6 = "", "", BZ6*EXP(DATA!$B$4*(BY6-BX6)*24)) -> 546.74873 | CC6: =IF(CB6 = "", "", CB6*EXP(CA6*DATA!$B$4)*EXP(-CA6*DATA!$B$5)) -> 676.71103 | CD6: =CB6*$S$6/$T$6 -> 0.00017218505 | CE6: =CC6*($S$6/$T$6) -> 0.00021311347 | CF6: 44330.363 | CG6: 44334.5 | CH6: 77.5 | CI6: =IF(CF6 = "", "", 24*(CF6-$L6)) -> 89.516667 | CJ6: =IF(CH6 = "", "", CH6*EXP(DATA!$B$4*(CG6-CF6)*24)) -> 153.89375 | CK6: =IF(CJ6 = "", "", CJ6*EXP(CI6*DATA!$B$4)*EXP(-CI6*DATA!$B$5)) -> 206.97798 | CL6: =CJ6*$S$6/$T$6 -> 4.8465046e-05 | CM6: =CK6*($S$6/$T$6) -> 6.5182616e-05 | CN6: =AA6 -> 63.075136 | CO6: =AG6 -> 31.574125 | CP6: =AM6 -> 13.338903 | CQ6: =AS6 -> 4.0208577 | CR6: =AY6 -> 1.1989652 | CS6: =Y6 -> 1.9666667 | CT6: =AE6 -> 16.5 | CU6: =AK6 -> 40.666667 | CV6: =AQ6 -> 64.683333 | CW6: =AW6 -> 88.516667 | CX6: {=LOGEST(CN6:CR6,CS6:CW6,TRUE,TRUE)} -> 0.95581407 | CY6: 71.608134 | CZ6: 0 | DA6: 2 | DB6: 4 | DC6: 10 | DD6: 18 | DE6: 24 | DF6: 26 | DG6: 34 | DH6: 42 | DI6: 48 | DJ6: 50 | DK6: 58 | DL6: 66 | DM6: 74 | DN6: =($CY$6*$CX$6^CZ6)/$I$6 -> 1.1199607 | DO6: =($CY$6*$CX$6^DA6)/$I$6 -> 1.0231743 | DP6: =($CY$6*$CX$6^DB6)/$I$6 -> 0.93475216 | DQ6: =($CY$6*$CX$6^DC6)/$I$6 -> 0.71274964 | DR6: =($CY$6*$CX$6^DD6)/$I$6 -> 0.49650586 | DS6: =($CY$6*$CX$6^DE6)/$I$6 -> 0.37858631 | DT6: =($CY$6*$CX$6^DF6)/$I$6 -> 0.34586908 | DU6: =($CY$6*$CX$6^DG6)/$I$6 -> 0.24093457 | ... EA6: =($CY$6*$CX$6^DM6)/$I$6 -> 0.039521732 | EB6: {=LOGEST(DN6:EA6, CZ6:DM6, TRUE, TRUE)} -> 0.95581407 | EC6: 1.1199607 | ED6: =-LN(DW6/DN6)/DI6 -> 0.045191868 | EE6: =LN(2)/ED6 -> 15.337874 | EF6: =(EC6*EE6)/LN(2) -> 24.782351 | EG6: =BG6 -> 0.0030876123 | EH6: =BO6 -> 0.0016824738 | EI6: =BW6 -> 0.00057513875 | EJ6: =CE6 -> 0.00021311347 | EK6: =CM6 -> 6.5182616e-05 | EL6: =BC6 -> 0.83333333 | EM6: =BK6 -> 16.383333 | EN6: =BS6 -> 41.716667 | EO6: =CA6 -> 64.416667 | EP6: =CI6 -> 89.516667 | EQ6: {=LOGEST(EG6:EK6, EL6:EP6, TRUE, TRUE)} -> 0.95745351 | ER6: 0.0033689911 | ES6: 0 | ET6: 2 | EU6: 4 | EV6: 10 | EW6: 18 | EX6: 24 | EY6: 26 | EZ6: 34 | FA6: 42 | FB6: 48 | FC6: 50 | FD6: 58 | FE6: 66 | FF6: 72 | FG6: 78 | FH6: 84 | FI6: 90 | FJ6: 96 | FK6: =($ER6*$EQ$6^ES6)/$I6 -> 5.2691469e-05 | FL6: =($ER6*$EQ$6^ET6)/$I6 -> 4.8303177e-05 | FM6: =($ER6*$EQ$6^EU6)/$I6 -> 4.4280355e-05 | FN6: =($ER6*$EQ$6^EV6)/$I6 -> 3.4112792e-05 | FO6: =($ER6*$EQ$6^EW6)/$I6 -> 2.4091223e-05 | FP6: =($ER6*$EQ$6^EX6)/$I6 -> 1.8559447e-05 | FQ6: =($ER6*$EQ$6^EY6)/$I6 -> 1.7013765e-05 | FR6: =($ER6*$EQ$6^EZ6)/$I6 -> 1.2015504e-05 | ... GB6: =($ER6*$EQ$6^FJ6)/$I6 -> 8.1103425e-07 | GC6: {=LOGEST(FK6:GB6, ES6:FJ6, TRUE, TRUE)} -> 0.95745351 | GD6: 5.2691469e-05 | GE6: =-LN(#REF!/#REF!)/#REF! -> #REF! | GF6: =LN(2)/GE6 -> #REF! | GG6: =(GF6*DATA!$B$3)/(DATA!$B$3+#REF!) -> #REF! | GH6: =(GG6*GD6)/LN(2) -> #REF! | GI6: =DATA!$B$6/DW6 -> 23.129418 | GK6: =IF(G6<F6, 0.0188*(G6^(-2/3)), 0.0188*F6^(-2/3)) -> 0.00098017809 | GL6: =GK6*EF6 + GH6*DATA!$B$8 -> #REF! | GM6: =DATA!$B$7/GL6 -> #REF! | GO6: =GI6 -> 23.129418 | GP6: =ROUNDDOWN(GO6*27.027,0) -> 625 | GQ6: =GM6 -> #REF! | GR6: =ROUNDDOWN(GQ6 * 27.027,0) -> #REF! | GW6: =Y6 -> 1.9666667 | GY6: =IF(GX6 = "", "", 0.001 * 4/3 *3.14159265*(GX6/2)^3) | GZ6: =IF(GS6 = "", "", GS6/GY6) | HD6: =AB6 -> 44327.321 | HE6: =AE6 -> 16.5 | HI6: =AH6 -> 44328.328 | HJ6: =AK6 -> 40.666667 | HN6: =AN6 -> 44329.328 | HO6: =AQ6 -> 64.683333 | HS6: =AT6 -> 44330.322 | HT6: =AW6 -> 88.516667 | IL6: =IF(IK6="","",-LN(IJ6)) | IM6: =LN(2)/IL6 -> #VALUE!
A7: 6 | C7: F | E7: 150 | F7: 71.2 | G7: =IF(C7 = "M", 65.76+(1.452*(E7-152)), 62.34+(1.247*(E7-152))) -> 59.846 | H7: 71.2 | I7: =AA7*EXP(DATA!$B$4*Y7) -> 70.084106 | L7: 44326.619 | M7: 44326.619 | N7: 11.67 | O7: 44334.5 | P7: 200 | Q7: 50153.5 | S7: =N7/P7 -> 0.05835 | T7: =Q7*EXP((O7-M7)*24*DATA!$B$4) -> 185281.99 | U7: =T7/S7 -> 3175355.5 | V7: 44326.68 | W7: 304.7 | X7: 226626.83 | Y7: =IF(V7="","",(V7-$L7)*24) -> 1.45 | Z7: =IF(W7 = "", "", W7*X7/1000000) -> 69.053195 | AA7: =IF(Z7 = "", "", Z7*EXP(Y7*DATA!$B$4)*EXP(-DATA!$B$5*'Inputs-new'!Y7)) -> 69.385469 | AB7: 44327.292 | AC7: 123.6 | AD7: 225232.55 | AE7: =IF(AB7="","",(AB7-$L7)*24) -> 16.133333 | AF7: =IF(AC7 = "", "", AC7*AD7/1000000) -> 27.838743 | AG7: =IF(AF7 = "", "", AF7*EXP(AE7*DATA!$B$4)*EXP(-DATA!$B$5*'Inputs-new'!AE7)) -> 29.366043 | AH7: 44328.295 | AI7: 28.6 | AJ7: 271844.94 | AK7: =IF(AH7="","",(AH7-$L7)*24) -> 40.216667 | AL7: =IF(AI7 = "", "", AI7*AJ7/1000000) -> 7.7747653 | AM7: =IF(AL7 = "", "", AL7*EXP(AK7*DATA!$B$4)*EXP(-DATA!$B$5*'Inputs-new'!AK7)) -> 8.881965 | AQ7: =IF(AN7="","",(AN7-$L7)*24) | AR7: =IF(AO7 = "", "", AO7*AP7/1000000) | AS7: =IF(AR7 = "", "", AR7*EXP(AQ7*DATA!$B$4)*EXP(-DATA!$B$5*'Inputs-new'!AQ7)) | AW7: =IF(AT7="","",(AT7-$L7)*24) | AX7: =IF(AU7 = "", "", AU7*AV7/1000000) | AY7: =IF(AX7 = "", "", AX7*EXP(AW7*DATA!$B$4)*EXP(-DATA!$B$5*'Inputs-new'!AW7)) | AZ7: 44326.628 | BA7: 44334.479 | BB7: 2831.75 | BC7: =IF(AZ7 = "", "", 24*(AZ7-$L7)) -> 0.21666667 | BD7: =IF(BB7 = "", "", BB7*EXP(DATA!$B$4*(BA7-AZ7)*24)) -> 10409.656 | BE7: =IF(BD7 = "", "", BD7*EXP(BC7*DATA!$B$4)*EXP(-BC7*DATA!$B$5)) -> 10417.125 | BF7: =BD7*$S$7/$T$7 -> 0.0032782647 | BG7: =BE7*$S$7/$T$7 -> 0.003280617 | BH7: 44327.333 | BI7: 44334.479 | BJ7: 1888.75 | BK7: =IF(BH7 = "", "", 24*(BH7-$L7)) -> 17.133333 | BL7: =IF(BJ7 = "", "", BJ7*EXP(DATA!$B$4*(BI7-BH7)*24)) -> 6177.2352 | BM7: =IF(BL7 = "", "", BL7*EXP(BK7*DATA!$B$4)*EXP(-BK7*DATA!$B$5)) -> 6537.7408 | BN7: =BL7*$S$7/$T$7 -> 0.0019453681 | BO7: =BM7*($S$7/$T$7) -> 0.0020589005 | BP7: 44328.333 | BQ7: 44334.479 | BR7: 592.5 | BS7: =IF(BP7 = "", "", 24*(BP7-$L7)) -> 41.133333 | BT7: =IF(BR7 = "", "", BR7*EXP(DATA!$B$4*(BQ7-BP7)*24)) -> 1641.6904 | BU7: =IF(BT7 = "", "", BT7*EXP(BS7*DATA!$B$4)*EXP(-BS7*DATA!$B$5)) -> 1881.1827 | BV7: =BT7*$S$7/$T$7 -> 0.00051700997 | BW7: =BU7*$S$7/$T$7 -> 0.00059243217 | BX7: 44329.337 | BY7: 44334.479 | BZ7: 186.5 | CA7: =IF(BX7 = "", "", 24*(BX7-$L7)) -> 65.216667 | CB7: =IF(BZ7 = "", "", BZ7*EXP(DATA!$B$4*(BY7-BX7)*24)) -> 437.53716 | CC7: =IF(CB7 = "", "", CB7*EXP(CA7*DATA!$B$4)*EXP(-CA7*DATA!$B$5)) -> 542.97599 | CD7: =CB7*$S$7/$T$7 -> 0.00013779155 | CE7: =CC7*($S$7/$T$7) -> 0.00017099692 | CI7: =IF(CF7 = "", "", 24*(CF7-$L7)) | CJ7: =IF(CH7 = "", "", CH7*EXP(DATA!$B$4*(CG7-CF7)*24)) | CK7: =IF(CJ7 = "", "", CJ7*EXP(CI7*DATA!$B$4)*EXP(-CI7*DATA!$B$5)) | CL7: =CJ7*$S$4/$T$4 -> #VALUE! | CM7: =CK7*($S$4/$T$4) -> #VALUE! | CN7: =AA7 -> 69.385469 | CO7: =AG7 -> 29.366043 | CP7: =AM7 -> 8.881965 | CQ7: =AS7 | CR7: =AY7 | CS7: =Y7 -> 1.45 | CT7: =AE7 -> 16.133333 | CU7: =AK7 -> 40.216667 | CV7: =AQ7 | CW7: =AW7 | CX7: {=LOGEST(CN7:CQ7,CS7:CV7,TRUE,TRUE)} -> #VALUE! | CY7: #VALUE! | CZ7: 0 | DA7: 2 | DB7: 4 | DC7: 10 | DD7: 18 | DE7: 24 | DF7: 26 | DG7: 34 | DH7: 42 | DI7: 48 | DJ7: 50 | DK7: 58 | DL7: 66 | DM7: 74 | DN7: =($CY$7*$CX$7^CZ7)/$I$7 -> #VALUE! | DO7: =($CY$7*$CX$7^DA7)/$I$7 -> #VALUE! | DP7: =($CY$7*$CX$7^DB7)/$I$7 -> #VALUE! | DQ7: =($CY$7*$CX$7^DC7)/$I$7 -> #VALUE! | DR7: =($CY$7*$CX$7^DD7)/$I$7 -> #VALUE! | DS7: =($CY$7*$CX$7^DE7)/$I$7 -> #VALUE! | DT7: =($CY$7*$CX$7^DF7)/$I$7 -> #VALUE! | DU7: =($CY$7*$CX$7^DG7)/$I$7 -> #VALUE! | ... EA7: =($CY$7*$CX$7^DM7)/$I$7 -> #VALUE! | EB7: {=LOGEST(DN7:EA7,CZ7:DM7,TRUE,TRUE)} -> #VALUE! | EC7: #VALUE! | ED7: =-LN(DW7/DN7)/DI7 -> #VALUE! | EE7: =LN(2)/ED7 -> #VALUE! | EF7: =(EC7*EE7)/LN(2) -> #VALUE! | EG7: =BG7 -> 0.003280617 | EH7: =BO7 -> 0.0020589005 | EI7: =BW7 -> 0.00059243217 | EJ7: =CE7 -> 0.00017099692 | EK7: =CM7 -> #VALUE! | EL7: =BC7 -> 0.21666667 | EM7: =BK7 -> 17.133333 | EN7: =BS7 -> 41.133333 | EO7: =CA7 -> 65.216667 | EP7: =CI7 | EQ7: {=LOGEST(EG7:EJ7, EL7:EO7, TRUE, TRUE)} -> 0.95451346 | ER7: 0.0038374646 | ES7: 0 | ET7: 2 | EU7: 4 | EV7: 10 | EW7: 18 | EX7: 24 | EY7: 26 | EZ7: 34 | FA7: 42 | FB7: 48 | FC7: 50 | FD7: 58 | FE7: 66 | FF7: 72 | FG7: 78 | FH7: 84 | FI7: 90 | FJ7: 96 | FK7: =($ER7*$EQ$7^ES7)/$I7 -> 5.4755134e-05 | FL7: =($ER7*$EQ$7^ET7)/$I7 -> 4.988718e-05 | FM7: =($ER7*$EQ$7^EU7)/$I7 -> 4.5452007e-05 | FN7: =($ER7*$EQ$7^EV7)/$I7 -> 3.4375213e-05 | FO7: =($ER7*$EQ$7^EW7)/$I7 -> 2.3686552e-05 | FP7: =($ER7*$EQ$7^EX7)/$I7 -> 1.7914066e-05 | FQ7: =($ER7*$EQ$7^EY7)/$I7 -> 1.6321433e-05 | FR7: =($ER7*$EQ$7^EZ7)/$I7 -> 1.1246431e-05 | ... GB7: =($ER7*$EQ$7^FJ7)/$I7 -> 6.2733884e-07 | GC7: {=LOGEST(FK7:GB7, ES7:FJ7, TRUE, TRUE)} -> 0.95451346 | GD7: 5.4755134e-05 | GE7: =-LN(#REF!/#REF!)/#REF! -> #REF! | GF7: =LN(2)/GE7 -> #REF! | GG7: =(GF7*DATA!$B$3)/(DATA!$B$3+#REF!) -> #REF! | GH7: =(GG7*GD7)/LN(2) -> #REF! | GI7: =DATA!$B$6/DW7 -> #VALUE! | GK7: =IF(G7<F7, 0.0188*(G7^(-2/3)), 0.0188*F7^(-2/3)) -> 0.001228762 | GL7: =GK7*EF7 + GH7*DATA!$B$8 -> #VALUE! | GM7: =DATA!$B$7/GL7 -> #VALUE! | GO7: =GI7 -> #VALUE! | GP7: =ROUNDDOWN(GO7*27.027,0) -> #VALUE! | GQ7: =GM7 -> #VALUE! | GR7: =ROUNDDOWN(GQ7 * 27.027,0) -> #VALUE! | GW7: =Y7 -> 1.45 | GY7: =IF(GX7 = "", "", 0.001 * 4/3 *3.14159265*(GX7/2)^3) | GZ7: =IF(GS7 = "", "", GS7/GY7) | HD7: =AB7 -> 44327.292 | HE7: =AE7 -> 16.133333 | HI7: =AH7 -> 44328.295 | HJ7: =AK7 -> 40.216667 | HN7: =AN7 -> 0 | HO7: =AQ7 | HS7: =AT7 -> 0 | HT7: =AW7 | IL7: =IF(IK7="","",-LN(IJ7)) | IM7: =LN(2)/IL7 -> #VALUE!
A8: 7 | C8: M | E8: 175 | F8: 84 | G8: =IF(C8 = "M", 65.76+(1.452*(E8-152)), 62.34+(1.247*(E8-152))) -> 99.156 | H8: 74.91 | I8: =AA8*EXP(DATA!$B$4*Y8) -> 63.863495 | J8: =AA8*EXP(DATA!$B$5*'Inputs-new'!Y8) -> 63.533122 | L8: 44376.438 | M8: 44376.438 | N8: 7.77 | O8: 44376.438 | P8: 200 | Q8: 78275.5 | S8: =N8/P8 -> 0.03885 | T8: =Q8*EXP((O8-M8)*24*DATA!$B$4) -> 78275.5 | U8: =T8/S8 -> 2014813.4 | V8: 44376.503 | W8: 210.1 | X8: 299139.01 | Y8: =IF(V8="","",(V8-$L8)*24) -> 1.5666667 | Z8: =IF(W8 = "", "", W8*X8/1000000) -> 62.849106 | AA8: =IF(Z8 = "", "", Z8*EXP(Y8*DATA!$B$4)*EXP(-DATA!$B$5*'Inputs-new'!Y8)) -> 63.175922 | AB8: 44377.296 | AC8: 99.4 | AD8: 306135.4 | AE8: =IF(AB8="","",(AB8-$L8)*24) -> 20.583333 | AF8: =IF(AC8 = "", "", AC8*AD8/1000000) -> 30.429859 | AG8: =IF(AF8 = "", "", AF8*EXP(AE8*DATA!$B$4)*EXP(-DATA!$B$5*'Inputs-new'!AE8)) -> 32.5757 | AH8: 44378.385 | AI8: 44.8 | AJ8: 286565.13 | AK8: =IF(AH8="","",(AH8-$L8)*24) -> 46.733333 | AL8: =IF(AI8 = "", "", AI8*AJ8/1000000) -> 12.838118 | AM8: =IF(AL8 = "", "", AL8*EXP(AK8*DATA!$B$4)*EXP(-DATA!$B$5*'Inputs-new'!AK8)) -> 14.986234 | AQ8: =IF(AN8="","",(AN8-$L8)*24) | AR8: =IF(AO8 = "", "", AO8*AP8/1000000) | AS8: =IF(AR8 = "", "", AR8*EXP(AQ8*DATA!$B$4)*EXP(-DATA!$B$5*'Inputs-new'!AQ8)) | AW8: =IF(AT8="","",(AT8-$L8)*24) | AX8: =IF(AU8 = "", "", AU8*AV8/1000000) | AY8: =IF(AX8 = "", "", AX8*EXP(AW8*DATA!$B$4)*EXP(-DATA!$B$5*'Inputs-new'!AW8)) | AZ8: 44376.5 | BA8: 44378.625 | BB8: 7020.25 | BC8: =IF(AZ8 = "", "", 24*(AZ8-$L8)) -> 1.4833333 | BD8: =IF(BB8 = "", "", BB8*EXP(DATA!$B$4*(BA8-AZ8)*24)) -> 9985.9218 | BE8: =IF(BD8 = "", "", BD8*EXP(BC8*DATA!$B$4)*EXP(-BC8*DATA!$B$5)) -> 10035.08 | BF8: =BD8*$S$8/$T$8 -> 0.0049562515 | BG8: =BE8*$S$8/$T$8 -> 0.0049806498 | BH8: 44377.351 | BI8: 44378.625 | BJ8: 3177 | BK8: =IF(BH8 = "", "", 24*(BH8-$L8)) -> 21.9 | BL8: =IF(BJ8 = "", "", BJ8*EXP(DATA!$B$4*(BI8-BH8)*24)) -> 3924.5381 | BM8: =IF(BL8 = "", "", BL8*EXP(BK8*DATA!$B$4)*EXP(-BK8*DATA!$B$5)) -> 4219.6402 | BN8: =BL8*$S$8/$T$8 -> 0.001947842 | BO8: =BM8*($S$8/$T$8) -> 0.0020943082 | BP8: 44378.436 | BQ8: 44378.625 | BR8: 1263 | BS8: =IF(BP8 = "", "", 24*(BP8-$L8)) -> 47.95 | BT8: =IF(BR8 = "", "", BR8*EXP(DATA!$B$4*(BQ8-BP8)*24)) -> 1303.1863 | BU8: =IF(BT8 = "", "", BT8*EXP(BS8*DATA!$B$4)*EXP(-BS8*DATA!$B$5)) -> 1527.3794 | BV8: =BT8*$S$8/$T$8 -> 0.00064680249 | BW8: =BU8*$S$8/$T$8 -> 0.00075807488 | CA8: =IF(BX8 = "", "", 24*(BX8-$L8)) | CB8: =IF(BZ8 = "", "", BZ8*EXP(DATA!$B$4*(BY8-BX8)*24)) | CC8: =IF(CB8 = "", "", CB8*EXP(CA8*DATA!$B$4)*EXP(-CA8*DATA!$B$5)) | CD8: =CB8*$S$8/$T$8 -> #VALUE! | CE8: =CC8*($S$8/$T$8) -> #VALUE! | CI8: =IF(CF8 = "", "", 24*(CF8-$L8)) | CJ8: =IF(CH8 = "", "", CH8*EXP(DATA!$B$4*(CG8-CF8)*24)) | CK8: =IF(CJ8 = "", "", CJ8*EXP(CI8*DATA!$B$4)*EXP(-CI8*DATA!$B$5)) | CL8: =CJ8*$S$4/$T$4 -> #VALUE! | CM8: =CK8*($S$4/$T$4) -> #VALUE! | CN8: =AA8 -> 63.175922 | CO8: =AG8 -> 32.5757 | CP8: =AM8 -> 14.986234 | CQ8: =AS8 | CR8: =AY8 | CS8: =Y8 -> 1.5666667 | CT8: =AE8 -> 20.583333 | CU8: =AK8 -> 46.733333 | CV8: =AQ8 | CW8: =AW8 | CX8: {=LOGEST(CN8:CP8,CS8:CU8,TRUE,TRUE)} -> 0.96877358 | CY8: 64.972691 | CZ8: 0 | DA8: 2 | DB8: 4 | DC8: 10 | DD8: 18 | DE8: 24 | DF8: 26 | DG8: 34 | DH8: 42 | DI8: 48 | DJ8: 50 | DK8: 58 | DL8: 66 | DM8: 74 | DN8: =($CY$8*$CX$8^CZ8)/$J$8 -> 1.0226586 | DO8: =($CY$8*$CX$8^DA8)/$J$8 -> 0.95978782 | DP8: =($CY$8*$CX$8^DB8)/$J$8 -> 0.90078223 | DQ8: =($CY$8*$CX$8^DC8)/$J$8 -> 0.74465231 | DR8: =($CY$8*$CX$8^DD8)/$J$8 -> 0.57773921 | DS8: =($CY$8*$CX$8^DE8)/$J$8 -> 0.47760138 | DT8: =($CY$8*$CX$8^DF8)/$J$8 -> 0.44823953 | DU8: =($CY$8*$CX$8^DG8)/$J$8 -> 0.34776707 | ... EA8: =($CY$8*$CX$8^DM8)/$J$8 -> 0.097764231 | EB8: {=LOGEST(DN8:EA8,CZ8:DM8,TRUE,TRUE)} -> 0.96877358 | EC8: 1.0226586 | ED8: =-LN(DW8/DN8)/DI8 -> 0.031724354 | EE8: =LN(2)/ED8 -> 21.849056 | EF8: =(EC8*EE8)/LN(2) -> 32.235757 | EG8: =BG8 -> 0.0049806498 | EH8: =BO8 -> 0.0020943082 | EI8: =BW8 -> 0.00075807488 | EJ8: =CE8 -> #VALUE! | EK8: =CM8 -> #VALUE! | EL8: =BC8 -> 1.4833333 | EM8: =BK8 -> 21.9 | EN8: =BS8 -> 47.95 | EO8: =CA8 | EP8: =CI8 | EQ8: {=LOGEST(EG8:EI8, EL8:EN8, TRUE, TRUE)} -> 0.9603612 | ER8: 0.0052120939 | ES8: 0 | ET8: 2 | EU8: 4 | EV8: 10 | EW8: 18 | EX8: 24 | EY8: 26 | EZ8: 34 | FA8: 42 | FB8: 48 | FC8: 50 | FD8: 58 | FE8: 66 | FF8: 72 | FG8: 78 | FH8: 84 | FI8: 90 | FJ8: 96 | FK8: =($ER8*$EQ$8^ES8)/$H8 -> 6.9578078e-05 | FL8: =($ER8*$EQ$8^ET8)/$H8 -> 6.417142e-05 | FM8: =($ER8*$EQ$8^EU8)/$H8 -> 5.9184892e-05 | FN8: =($ER8*$EQ$8^EV8)/$H8 -> 4.643212e-05 | FO8: =($ER8*$EQ$8^EW8)/$H8 -> 3.3596603e-05 | FP8: =($ER8*$EQ$8^EX8)/$H8 -> 2.6357427e-05 | FQ8: =($ER8*$EQ$8^EY8)/$H8 -> 2.4309288e-05 | FR8: =($ER8*$EQ$8^EZ8)/$H8 -> 1.7589322e-05 | ... GB8: =($ER8*$EQ$8^FJ8)/$H8 -> 1.4328304e-06 | GC8: {=LOGEST(FK8:GB8, ES8:FJ8, TRUE, TRUE)} -> 0.9603612 | GD8: 6.9578078e-05 | GE8: =-LN(FT8/FK8)/FB8 -> 0.04044581 | GF8: =LN(2)/GE8 -> 17.137676 | GG8: =(GF8*DATA!$B$3)/(DATA!$B$3+GF8) -> 15.737387 | GH8: =(GG8*GD8)/LN(2) -> 0.0015797181 | GI8: =DATA!$B$6/DW8 -> 13.27062 | GK8: =IF(G8<F8, 0.0188*(G8^(-2/3)), 0.0188*F8^(-2/3)) -> 0.00098017809 | GL8: =GK8*EF8 + GH8*DATA!$B$8 -> 0.20220634 | GM8: =DATA!$B$7/GL8 -> 9.8908866 | GO8: =GI8 -> 13.27062 | GP8: =ROUNDDOWN(GO8*27.027,0) -> 358 | GQ8: =GM8 -> 9.8908866 | GR8: =ROUNDDOWN(GQ8 * 27.027,0) -> 267 | GS8: 13.2 | GT8: 1.84 | GU8: 0.53 | GV8: =V8 -> 44376.503 | GW8: =Y8 -> 1.5666667 | GX8: 10 | GY8: =IF(GX8 = "", "", 0.001 * 4/3 *3.14159265*(GX8/2)^3) -> 0.52359878 | GZ8: =IF(GS8="","",((GS8-GU8)*GT8/GY8)) -> 44.524168 | HA8: 60.3 | HB8: 1.99 | HC8: 4.19 | HD8: =AB8 -> 44377.296 | HE8: =AE8 -> 20.583333 | HF8: 27.8 | HG8: 1.64 | HH8: 1.1 | HI8: =AH8 -> 44378.385 | HJ8: =AK8 -> 46.733333 | HN8: =AN8 -> 0 | HO8: =AQ8 | HS8: =AT8 -> 0 | HT8: =AW8 | HU8: =GW8 -> 1.5666667 | HV8: =HE8 -> 20.583333 | HW8: =HJ8 -> 46.733333 | HZ8: =(GS8-GU8)*GT8/GY8 -> 44.524168 | IA8: =(HA8-HC8)*HB8/GY8 -> 213.25279 | IB8: =(HF8-HH8)*HG8/GY8 -> 83.62892 | IJ8: {=LOGEST(IA8:IB8, HV8:HW8, TRUE, FALSE)} -> 0.96483623 | IK8: 445.54478 | IL8: =IF(IK8="","",-LN(IJ8)) -> 0.035796898 | IM8: =LN(2)/IL8 -> 19.363331 | IN8: =(IM8*DATA!$B$3)/(DATA!B3+'Inputs-new'!IM8) -> 17.594487 | IO8: =IK8 -> 445.54478 | IP8: =IO8/I8 -> 6.9765173 | IQ8: =IN8/LN(2) -> 25.383479 | IR8: =IQ8*IP8/1000 -> 0.17708828 | IS8: =110.01*(GY8^0.0275) -> 108.06987 | IT8: =IS8*IR8 -> 19.137907 | IU8: =IT8/1000 -> 0.019137907 | IV8: =(80/IU8)/1000 -> 4.1801854
A9: 8 | C9: F | E9: 173 | F9: 63.2 | G9: =IF(C9 = "M", 65.76+(1.452*(E9-152)), 62.34+(1.247*(E9-152))) -> 88.527 | H9: 53.84 | I9: =Z9*EXP(DATA!$B$4*Y9) -> 42.544521 | J9: =AA9*EXP(DATA!$B$5*'Inputs-new'!Y9) -> 42.544521 | L9: 44690.67 | M9: 44690.618 | N9: 1.01 | S9: =N9/P9 -> #DIV/0! | T9: =Q9*EXP((O9-M9)*24*DATA!$B$4) -> 0 | U9: =T9/S9 -> #DIV/0! | V9: 44690.751 | W9: 205.3 | X9: 204481.18 | Y9: =IF(V9="","",(V9-$L9)*24) -> 1.9333333 | Z9: =IF(W9 = "", "", W9*X9/1000000) -> 41.979986 | AA9: =IF(Z9 = "", "", Z9*EXP(Y9*DATA!$B$4)*EXP(-DATA!$B$5*'Inputs-new'!Y9)) -> 42.249537 | AB9: 44691.321 | AC9: 118.1 | AD9: 197253.58 | AE9: =IF(AB9="","",(AB9-$L9)*24) -> 15.616667 | AF9: =IF(AC9 = "", "", AC9*AD9/1000000) -> 23.295648 | AG9: =IF(AF9 = "", "", AF9*EXP(AE9*DATA!$B$4)*EXP(-DATA!$B$5*'Inputs-new'!AE9)) -> 24.531706 | AH9: 44692.319 | AI9: 49.9 | AJ9: 206486.31 | AK9: =IF(AH9="","",(AH9-$L9)*24) -> 39.566667 | AL9: =IF(AI9 = "", "", AI9*AJ9/1000000) -> 10.303667 | AM9: =IF(AL9 = "", "", AL9*EXP(AK9*DATA!$B$4)*EXP(-DATA!$B$5*'Inputs-new'!AK9)) -> 11.745704 | AN9: 44693.297 | AO9: 22.1 | AP9: 194052 | AQ9: =IF(AN9="","",(AN9-$L9)*24) -> 63.05 | AR9: =IF(AO9 = "", "", AO9*AP9/1000000) -> 4.2885492 | AS9: =IF(AR9 = "", "", AR9*EXP(AQ9*DATA!$B$4)*EXP(-DATA!$B$5*'Inputs-new'!AQ9)) -> 5.2839773 | AT9: 44694.297 | AU9: 13.2 | AV9: 224672 | AW9: =IF(AT9="","",(AT9-$L9)*24) -> 87.05 | AX9: =IF(AU9 = "", "", AU9*AV9/1000000) -> 2.9656704 | AY9: =IF(AX9 = "", "", AX9*EXP(AW9*DATA!$B$4)*EXP(-DATA!$B$5*'Inputs-new'!AW9)) -> 3.9562122 | BC9: =IF(AZ9 = "", "", 24*(AZ9-$L9)) | BD9: =IF(BB9 = "", "", BB9*EXP(DATA!$B$4*(BA9-AZ9)*24)) | BE9: =IF(BD9 = "", "", BD9*EXP(BC9*DATA!$B$4)*EXP(-BC9*DATA!$B$5)) | BF9: =BD9*$S9/$T9 -> #VALUE! | BG9: =BE9*$S9/$T9 -> #VALUE! | BK9: =IF(BH9 = "", "", 24*(BH9-$L9)) | BL9: =IF(BJ9 = "", "", BJ9*EXP(DATA!$B$4*(BI9-BH9)*24)) | BM9: =IF(BL9 = "", "", BL9*EXP(BK9*DATA!$B$4)*EXP(-BK9*DATA!$B$5)) | BN9: =BL9*$S9/$T9 -> #VALUE! | BO9: =BM9*($S9/$T9) -> #VALUE! | BS9: =IF(BP9 = "", "", 24*(BP9-$L9)) | BT9: =IF(BR9 = "", "", BR9*EXP(DATA!$B$4*(BQ9-BP9)*24)) | BU9: =IF(BT9 = "", "", BT9*EXP(BS9*DATA!$B$4)*EXP(-BS9*DATA!$B$5)) | BV9: =BT9*$S9/$T9 -> #VALUE! | BW9: =BU9*$S9/$T9 -> #VALUE! | CA9: =IF(BX9 = "", "", 24*(BX9-$L9)) | CB9: =IF(BZ9 = "", "", BZ9*EXP(DATA!$B$4*(BY9-BX9)*24)) | CC9: =IF(CB9 = "", "", CB9*EXP(CA9*DATA!$B$4)*EXP(-CA9*DATA!$B$5)) | CD9: =CB9*$S9/$T9 -> #VALUE! | CE9: =CC9*($S9/$T9) -> #VALUE! | CI9: =IF(CF9 = "", "", 24*(CF9-$L9)) | CJ9: =IF(CH9 = "", "", CH9*EXP(DATA!$B$4*(CG9-CF9)*24)) | CK9: =IF(CJ9 = "", "", CJ9*EXP(CI9*DATA!$B$4)*EXP(-CI9*DATA!$B$5)) | CL9: =CJ9*$S9/$T9 -> #VALUE! | CM9: =CK9*($S9/$T9) -> #VALUE! | CN9: =AA9 -> 42.249537 | CO9: =AG9 -> 24.531706 | CP9: =AM9 -> 11.745704 | CQ9: =AS9 -> 5.2839773 | CR9: =AY9 -> 3.9562122 | CS9: =Y9 -> 1.9333333 | CT9: =AE9 -> 15.616667 | CU9: =AK9 -> 39.566667 | CV9: =AQ9 -> 63.05 | CW9: =AW9 -> 87.05 | CX9: {=LOGEST(CN9:CR9,CS9:CW9,TRUE,TRUE)} -> 0.97184081 | CY9: 39.376124 | CZ9: 0 | DA9: 2 | DB9: 4 | DC9: 10 | DD9: 18 | DE9: 24 | DF9: 26 | DG9: 34 | DH9: 42 | DI9: 48 | DJ9: 50 | DK9: 58 | DL9: 66 | DM9: 74 | DN9: =($CY9*$CX9^CZ9)/$J9 -> 0.9255275 | DO9: =($CY9*$CX9^DA9)/$J9 -> 0.87413717 | DP9: =($CY9*$CX9^DB9)/$J9 -> 0.82560032 | DQ9: =($CY9*$CX9^DC9)/$J9 -> 0.69556967 | DR9: =($CY9*$CX9^DD9)/$J9 -> 0.55347969 | DS9: =($CY9*$CX9^DE9)/$J9 -> 0.46630758 | DT9: =($CY9*$CX9^DF9)/$J9 -> 0.44041564 | DU9: =($CY9*$CX9^DG9)/$J9 -> 0.35044816 | ... EA9: =($CY9*$CX9^DM9)/$J9 -> 0.11179671 | EB9: {=LOGEST(DN9:EA9,CZ9:DM9,TRUE,TRUE)} -> 0.97184081 | EC9: 0.9255275 | ED9: =-LN(DW9/DN9)/DI9 -> 0.028563266 | EE9: =LN(2)/ED9 -> 24.267084 | EF9: =(EC9*EE9)/LN(2) -> 32.402719 | EG9: =BG9 -> #VALUE! | EH9: =BO9 -> #VALUE! | EI9: =BW9 -> #VALUE! | EJ9: =CE9 -> #VALUE! | EK9: =CM9 -> #VALUE! | EL9: =BC9 | EM9: =BK9 | EN9: =BS9 | EO9: =CA9 | EP9: =CI9 | EQ9: {=LOGEST(EG9:EI9, EL9:EN9, TRUE, TRUE)} -> #VALUE! | ER9: #VALUE! | ES9: 0 | ET9: 2 | EU9: 4 | EV9: 10 | EW9: 18 | EX9: 24 | EY9: 26 | EZ9: 34 | FA9: 42 | FB9: 48 | FC9: 50 | FD9: 58 | FE9: 66 | FF9: 72 | FG9: 78 | FH9: 84 | FI9: 90 | FJ9: 96 | FK9: =($ER9*$EQ9^ES9)/$I9 -> #VALUE! | FL9: =($ER9*$EQ$9^ET9)/$I9 -> #VALUE! | FM9: =($ER9*$EQ$9^EU9)/$I9 -> #VALUE! | FN9: =($ER9*$EQ$9^EV9)/$I9 -> #VALUE! | FO9: =($ER9*$EQ$9^EW9)/$I9 -> #VALUE! | FP9: =($ER9*$EQ$9^EX9)/$I9 -> #VALUE! | FQ9: =($ER9*$EQ$9^EY9)/$I9 -> #VALUE! | FR9: =($ER9*$EQ$9^EZ9)/$I9 -> #VALUE! | FS9: =($ER9*$EQ$9^FA9)/$I9 -> #VALUE! | ... GB9: =($ER9*$EQ$9^FJ9)/$I9 -> #VALUE! | GC9: {=LOGEST(FK9:GB9, ES9:FJ9, TRUE, TRUE)} -> #VALUE! | GD9: #VALUE! | GE9: =-LN(FT9/FK9)/FB9 -> #VALUE! | GF9: =LN(2)/GE9 -> #VALUE! | GG9: =(GF9*DATA!$B$3)/(DATA!$B$3+GF9) -> #VALUE! | GH9: =(GG9*GD9)/LN(2) -> #VALUE! | GI9: =DATA!$B$6/DW9 -> 12.599 | GK9: =IF(G9<F9, 0.0188*(G9^(-2/3)), 0.0188*F9^(-2/3)) -> 0.0011848948 | GL9: =GK9*EF9 + GH9*DATA!$B$8 -> #VALUE! | GM9: =DATA!$B$7/GL9 -> #VALUE! | GO9: =GI9 -> 12.599 | GP9: =ROUNDDOWN(GO9*27.027,0) -> 340 | GQ9: =GM9 -> #VALUE! | GR9: =ROUNDDOWN(GQ9 * 27.027,0) -> #VALUE! | GS9: 1.04 | GT9: 25.03 | GU9: 0.375 | GV9: =V9 -> 44690.751 | GW9: =Y9 -> 1.9333333 | GX9: 13.2 | GY9: =IF(GX9 = "", "", 0.001 * 4/3 *3.14159265*(GX9/2)^3) -> 1.2042604 | GZ9: =IF(GS9="","",((GS9-GU9)*GT9/GY9)) -> 13.82172 | HA9: 1.28 | HB9: 18.11 | HC9: 0.2 | HD9: =AB9 -> 44691.321 | HE9: =AE9 -> 15.616667 | HF9: 0.826 | HG9: 16.87 | HH9: 0.075 | HI9: =AH9 -> 44692.319 | HJ9: =AK9 -> 39.566667 | HK9: 0.513 | HL9: 19.61 | HM9: 0.027 | HN9: =AN9 -> 44693.297 | HO9: =AQ9 -> 63.05 | HP9: 0.47 | HQ9: 18.1 | HR9: 0.022 | HS9: =AT9 -> 44694.297 | HT9: =AW9 -> 87.05 | HU9: =GW9 -> 1.9333333 | HV9: =HE9 -> 15.616667 | HW9: =HJ9 -> 39.566667 | HX9: =HO9 -> 63.05 | HY9: =HT9 -> 87.05 | HZ9: =(GS9-GU9)*GT9/GY9 -> 13.82172 | IA9: =(HA9-HC9)*HB9/GY9 -> 16.241337 | IB9: =(HF9-HH9)*HG9/GY9 -> 10.520457 | IC9: =(HK9-HM9)*HL9/$GY9 -> 7.9139526 | ID9: =(HP9-HR9)*HQ9/$GY9 -> 6.7334273 | IE9: =HZ9*EXP(DATA!$B$4*'Inputs-new'!HU9) -> 14.00759 | IF9: =IA9*EXP(DATA!$B$4*'Inputs-new'!HV9) -> 18.091838 | IG9: =IB9*EXP(DATA!$B$4*'Inputs-new'!HW9) -> 13.82809 | IH9: =IC9*EXP(DATA!$B$4*'Inputs-new'!HX9) -> 12.234534 | II9: =ID9*EXP(DATA!$B$4*'Inputs-new'!HY9) -> 12.28703 | IJ9: {=LOGEST(IF9:IH9, HV9:HX9, TRUE, FALSE)} -> 0.99177682 | IK9: 20.103617 | IL9: =IF(IK9="","",-LN(IJ9)) -> 0.008257178 | IM9: =LN(2)/IL9 -> 83.944803 | IN9: =(IM9*DATA!$B$3)/(DATA!$B$3+'Inputs-new'!IM9) -> 58.463913 | IO9: =IK9 -> 20.103617 | IP9: =IO9/I9 -> 0.47253128 | IQ9: =IN9/LN(2) -> 84.345598 | IR9: =IQ9*IP9/1000 -> 0.039855933 | IS9: =110.01*(GY9^0.0275) -> 110.57373 | IT9: =IS9*IR9 -> 4.4070194 | IU9: =IT9/1000 -> 0.0044070194 | IV9: =(80/IU9)/1000 -> 18.152859
